<mujoco model="Kondo_5">

    <compiler angle="radian"/>
    <size nconmax="20" nuserdata="210"/>
    <option integrator = "RK4" timestep = "0.002" 
            jacobian = "dense" cone = "elliptic" impratio = "100" 
            solver = "Newton" tolerance="1e-10"  
            noslip_iterations="0" noslip_tolerance="1e-6" >
        <!-- <flag energy="enable" fwdinv="enable" /> -->
    </option>
    
    <asset>
        <texture type="skybox" builtin="gradient" rgb1=".3 .5 .7" rgb2="0 0 0" width="512" height="512"/>
        <texture name="body" type="cube" builtin="flat" mark="cross" width="127" height="1278"
             rgb1="0.8 0.6 0.4" rgb2="0.8 0.6 0.4" markrgb="1 1 1" random="0.01"/>
        <material name="body" texture="body" texuniform="true" rgba="0.8 0.6 .4 1"/>
        <texture name="grid" type="2d" builtin="checker" width="512" height="512" rgb1=".1 .2 .3" rgb2=".2 .3 .4"/>
        <material name="grid" texture="grid" texrepeat="1 1" texuniform="true" reflectance=".2"/>
    </asset>

    <worldbody>
        <light name="spotlight1" mode="targetbodycom" target="Head"
           diffuse=".8 .8 .8" specular="0.3 0.3 0.3" pos="-10 10 3" cutoff="10"/>
        <light name="spotlight2" mode="targetbodycom" target="Torso"
           diffuse=".8 .8 .8" specular="0.3 0.3 0.3" pos="20 5 3" cutoff="10"/>
        
        <camera name="mycam1" pos="1.530 -0.516 0.147" xyaxes="0.282 0.959 -0.000 -0.161 0.047 0.986"/>
        <camera name="mycam2" pos="2.360 0.558 0.298" xyaxes="-0.184 0.983 0.000 -0.178 -0.033 0.984"/>

        <body name="Waist" pos="0 0 0.3"> 
            <joint name="floating_base_joint" type="free"/>
            <geom size="0.02525 0.038 0.018" pos="-0.00275 0 -0.022" type="box"/>

            <site name="waist_site" type="sphere" size="0.0025" pos="0.01 0 -0.05" rgba="1 0 0 1" />

            <body name="LeftHipBracket" pos="0.00875 0.02145 -0.03995">
                <joint name="Left_Hip_Yaw" pos="0 0 0" axis="0 0 1" limited="true" range="-2.356 2.356" frictionloss="0.12" />
                <geom size="0.02350 0.012 0.0155" pos="0 -0.0015 -0.0155" type="box"/>
                
                <body name="LeftPelvis" pos="0 -0.00455 -0.02235">
                    <joint name="Left_Hip_Roll" pos="0 0 0" axis="1 0 0" limited="true" range="-2.356 2.356" frictionloss="0.12" />
                    <geom size="0.016 0.02125 0.01175" pos="0 0.01125 -0.00025" type="box"/>
                    <geom size="0.01 0.02325 0.018" pos="0 0.01125 -0.03" type="box"/>
                    
                    <body name="LeftThigh" pos="-0.0008 0.0113 -0.0387">
                        <joint name="Left_Hip_Pitch" pos="0 0 0" axis="0 1 0" limited="true" range="-2.356 2.356" frictionloss="0.12" />
                        <geom size="0.01175 0.016 0.021" pos="0.00075 0 -0.011" type="box"/>
                        <geom size="0.016 0.021 0.01125" pos="0.006 0 -0.054" quat="0.355262 0.611381 0.61138 0.355269" type="box"/>
                        <geom size="0.016 0.01 0.0108" pos="0.003 0 -0.037" quat="0.164913 0.687606 0.687607 0.164921" type="box"/>
                        
                        <body name="LeftShin" pos="0.00015 0 -0.06375">
                            <joint name="Left_Knee_Pitch" pos="0 0 0" axis="0 1 0" limited="true" range="-2.356 2.356" frictionloss="0.12" />
                            <geom size="0.02325 0.018 0.01" pos="0.00425 0 -0.008" quat="0.608155 0.360758 0.360752 0.60816" type="box"/>
                            <geom size="0.016 0.021 0.0115" pos="0.004 0 -0.054" quat="0.402402 0.581438 0.581436 0.40241" type="box"/>
                            <geom size="0.0108 0.016 0.01" pos="0.0115 0 -0.028" type="box"/>
                            
                            <body name="LeftAnkle" pos="0.0003 -0.0002 -0.06435">
                                <joint name="Left_Ankle_Pitch" pos="0 0 0" axis="0 1 0" limited="true" range="-2.356 2.356" frictionloss="0.12" />
                                <geom size="0.016 0.02125 0.01175" pos="0 0 -0.037" type="box"/>
                                <geom size="0.01 0.02325 0.018" pos="0 0 -0.007" type="box"/>
                               
                                <body name="LeftFoot" pos="0 -0.01125 -0.037">
                                    <joint name="Left_Ankle_Roll" pos="0 0 0" axis="1 0 0" limited="true" range="-2.356 2.356" frictionloss="0.12" />
                                    <geom size="0.03 0.02 0.00825" pos="0 0.01125 -0.01825" type="box"/>
                                    <!-- <geom pos="0.04 -0.005 -0.02655" type="sphere" size="0.004" rgba="0 .9 0 1" density="0"/>
                                    <geom pos="0.04 0.03 -0.02655" type="sphere" size="0.004" rgba="0 .9 0 1" density="0"/>
                                    <geom pos="-0.03 -0.005 -0.02655" type="sphere" size="0.004" rgba="0 .9 0 1" density="0"/>
                                    <geom pos="-0.03 0.03 -0.02655" type="sphere" size="0.004" rgba="0 .9 0 1" density="0"/> -->
                                
                                    <site name="left_foot_site" type="sphere" size="0.0025" pos="0 0.0125 -0.02655" rgba="1 0 0 1" />                            
                                </body>
                            </body>
                        </body>
                    </body>
                </body>
            </body>

            <body name="RightHipBracket" pos="0.00875 -0.02145 -0.03995">
                <joint name="Right_Hip_Yaw" pos="0 0 0" axis="0 0 1" limited="true" range="-2.356 2.356" frictionloss="0.12" />
                <geom size="0.02350 0.012 0.0155" pos="0 -0.0015 -0.0155" type="box"/>
                
                <body name="RightPelvis" pos="0 0.00455 -0.02235">
                    <joint name="Right_Hip_Roll" pos="0 0 0" axis="1 0 0" limited="true" range="-2.356 2.356" frictionloss="0.12" />
                    <geom size="0.016 0.02125 0.01175" pos="0 -0.01125 -0.00025" type="box"/>
                    <geom size="0.01 0.02325 0.018" pos="0 -0.01125 -0.03" type="box"/>
                    
                    <body name="RightThigh" pos="-0.0008 -0.0113 -0.0387">
                        <joint name="Right_Hip_Pitch" pos="0 0 0" axis="0 1 0" limited="true" range="-2.356 2.356" frictionloss="0.12" />
                        <geom size="0.01175 0.016 0.021" pos="0.00075 0 -0.011" type="box"/>
                        <geom size="0.016 0.021 0.01125" pos="0.006 0 -0.054" quat="0.355262 0.611381 0.61138 0.355269" type="box"/>
                        <geom size="0.016 0.01 0.0108" pos="0.003 0 -0.037" quat="0.164913 0.687606 0.687607 0.164921" type="box"/>
                        
                        <body name="RightShin" pos="0.00015 0 -0.06375">
                            <joint name="Right_Knee_Pitch" pos="0 0 0" axis="0 1 0" limited="true" range="-2.356 2.356" frictionloss="0.12" />
                            <geom size="0.02325 0.018 0.01" pos="0.00425 0 -0.008" quat="0.608155 0.360758 0.360752 0.60816" type="box"/>
                            <geom size="0.016 0.021 0.0115" pos="0.004 0 -0.054" quat="0.402402 0.581438 0.581436 0.40241" type="box"/>
                            <geom size="0.0108 0.016 0.01" pos="0.0115 0 -0.028" type="box"/>
                            
                            <body name="RightAnkle" pos="0.0003 0.0002 -0.06435">
                                <joint name="Right_Ankle_Pitch" pos="0 0 0" axis="0 1 0" limited="true" range="-2.356 2.356" frictionloss="0.12" />
                                <geom size="0.016 0.02125 0.01175" pos="0 0 -0.0375" type="box"/>
                                <geom size="0.01 0.02325 0.018" pos="0 0 -0.007" type="box"/>
                                
                                <body name="RightFoot" pos="0 0.01125 -0.0375">
                                    <joint name="Right_Ankle_Roll" pos="0 0 0" axis="1 0 0" limited="true" range="-2.356 2.356" frictionloss="0.12" />
                                    <geom size="0.03 0.02 0.00825" pos="0 -0.01125 -0.01825" type="box"/>
                                    <!-- <geom pos="0.04 0.005 -0.02655" type="sphere" size="0.004" rgba="0 .9 0 1" density="0"/>
                                    <geom pos="0.04 -0.03 -0.02655" type="sphere" size="0.004" rgba="0 .9 0 1" density="0"/>
                                    <geom pos="-0.03 0.005 -0.02655" type="sphere" size="0.004" rgba="0 .9 0 1" density="0"/>
                                    <geom pos="-0.03 -0.03 -0.02655" type="sphere" size="0.004" rgba="0 .9 0 1" density="0"/> -->
                                    
                                    <site name="right_foot_site" type="sphere" size="0.0025" pos="0 -0.0125 -0.02655" rgba="1 0 0 1" />                        
                                </body>
                            </body>
                        </body>
                    </body>
                </body>
            </body>

            <body name="Torso" pos="0.02425 0 0.04715">
                <joint name="Waist_Yaw" pos="0 0 0" axis="0 0 1" limited="true" range="-2.356 2.356" frictionloss="0.12" />
                <geom size="0.04025 0.0445 0.03025" pos="-0.00475 0 -0.022" type="box"/>
                <geom size="0.02275 0.0525 0.044" pos="-0.06925 0 -0.012" type="box" density="100"/>

                <body name="Head" pos="-0.00395 0 0.0134">
                    <joint name="Neck_Yaw" pos="0 0 0" axis="0 0 1" limited="true" range="-2.356 2.356" frictionloss="0.12" />
                    <geom size="0.02475 0.016 0.019" pos="0.00225 0 0.02475" type="box"/>
                </body>
        
                <body name="LeftShoulderBracket" pos="-0.0041 0.04725 -0.0009">
                    <joint name="Left_Shoulder_Pitch" pos="0 0 0" axis="0 1 0" limited="true" range="-2.356 2.356" frictionloss="0.12" />
                    <geom size="0.02325 0.018 0.01" pos="0 0.0175 0" type="box"/>

                    <body name="LeftUpperArm" pos="0 0.02645 0">
                        <joint name="Left_Shoulder_Roll" pos="0 0 0" axis="1 0 0" limited="true" range="-2.356 2.356" frictionloss="0.12" />
                        <geom size="0.017775 0.0125 0.02125" pos="0.00025 0 -0.01125" type="box"/>
                        <geom size="0.02125 0.01125 0.015775" pos="-0.01175 -0.00025 -0.04825" type="box"/>
                        <geom size="0.02525 0.016775 0.00475" pos="-0.01125 -0.00025 -0.06875" type="box"/>

                        <body name="LeftElbowBracket" pos="0.00225 -0.00025 -0.07365">
                            <joint name="Left_Arm_Yaw" pos="0 0 0" axis="0 0 1" limited="true" range="-2.356 2.356" frictionloss="0.12" />
                            <geom size="0.0211 0.016 0.012" pos="-0.009 0 -0.012" type="box"/>

                            <body name="LeftForeArm" pos="0.0022 0 -0.0117">
                                <joint name="Left_Elbow_Pitch" pos="0 0 0" axis="0 1 0" limited="true" range="-2.356 2.356" frictionloss="0.12" />
                                <geom size="0.01 0.02325 0.018" pos="0 0 -0.009" type="box"/>
                                <geom size="0.0105 0.016 0.02" pos="0.001 0 -0.0465" type="box"/>
                                <geom size="0.0145 0.01175 0.012" pos="0.003 -0.00175 -0.0785" type="box"/>
                                <geom size="0.00325 0.00875 0.012" pos="0 0.001 -0.094" quat="0.653278 0.270601 0.653282 0.270602" type="box"/>
                            </body>
                        </body>
                    </body>
                </body>

                <body name="RightShoulderBracket" pos="-0.0041 -0.0475 -0.0009">
                    <joint name="Right_Shoulder_Pitch" pos="0 0 0" axis="0 1 0" limited="true" range="-2.356 2.356" frictionloss="0.12" />
                    <geom size="0.02325 0.018 0.01" pos="0 -0.0175 0" type="box"/>

                    <body name="RightUpperArm" pos="0 -0.02645 0">
                        <joint name="Right_Shoulder_Roll" pos="0 0 0" axis="1 0 0" limited="true" range="-2.356 2.356" frictionloss="0.12" />
                        <geom size="0.017775 0.0125 0.02125" pos="0.00025 0 -0.01125" type="box"/>
                        <geom size="0.02125 0.01125 0.015775" pos="-0.01175 0.00025 -0.04825" type="box"/>
                        <geom size="0.02525 0.016775 0.00475" pos="-0.01125 0.00025 -0.06875" type="box"/>

                        <body name="RightElbowBracket" pos="0.00225 0.00025 -0.07365">
                            <joint name="Right_Arm_Yaw" pos="0 0 0" axis="0 0 1" limited="true" range="-2.356 2.356" frictionloss="0.12" />
                            <geom size="0.0211 0.016 0.012" pos="-0.009 0 -0.012" type="box"/>

                            <body name="RightForeArm" pos="0.0022 0 -0.0117">
                                <joint name="Right_Elbow_Pitch" pos="0 0 0" axis="0 1 0" limited="true" range="-2.356 2.356" frictionloss="0.12" />
                                <geom size="0.01 0.02325 0.018" pos="0 0 -0.009" type="box"/>
                                <geom size="0.0105 0.016 0.02" pos="0.001 0 -0.0465" type="box"/>
                                <geom size="0.0145 0.01175 0.012" pos="0.003 0.00175 -0.0785" type="box"/>
                                <geom size="0.00325 0.00875 0.012" pos="0 -0.001 -0.094" quat="0.270593 0.653284 0.270596 0.653282" type="box"/>
                            </body>
                        </body>
                    </body>
                </body>
            </body>    
        </body>
    </worldbody>

    <actuator>
        <motor name="LHY" joint="Left_Hip_Yaw"/>
        <motor name="LHR" joint="Left_Hip_Roll"/>
        <motor name="LHP" joint="Left_Hip_Pitch"/>
        <motor name="LKP" joint="Left_Knee_Pitch"/>
        <motor name="LAP" joint="Left_Ankle_Pitch"/>
        <motor name="LAR" joint="Left_Ankle_Roll"/>

        <motor name="RHY" joint="Right_Hip_Yaw"/>
        <motor name="RHR" joint="Right_Hip_Roll"/>
        <motor name="RHP" joint="Right_Hip_Pitch"/>
        <motor name="RKP" joint="Right_Knee_Pitch"/>
        <motor name="RAP" joint="Right_Ankle_Pitch"/>
        <motor name="RAR" joint="Right_Ankle_Roll"/>

        <motor name="WY" joint="Waist_Yaw"/>
        <motor name="NY" joint="Neck_Yaw"/> 

        <motor name="LSP" joint="Left_Shoulder_Pitch"/>
        <motor name="LSR" joint="Left_Shoulder_Roll"/>
        <motor name="LAY" joint="Left_Arm_Yaw"/>
        <motor name="LEP" joint="Left_Elbow_Pitch"/>

        <motor name="RSP" joint="Right_Shoulder_Pitch"/>
        <motor name="RSR" joint="Right_Shoulder_Roll"/>
        <motor name="RAY" joint="Right_Arm_Yaw"/>
        <motor name="REP" joint="Right_Elbow_Pitch"/>  
    </actuator>

    <sensor>
        <framepos name="waist_site_pos" objtype="site" objname="waist_site"/>
        <framequat name="waist_site_quat" objtype="site" objname="waist_site"/>

        <framepos name="left_foot_site_pos" objtype="site" objname="left_foot_site"/>
        <framequat name="left_foot_site_quat" objtype="site" objname="left_foot_site"/>

        <framepos name="right_foot_site_pos" objtype="site" objname="right_foot_site"/>
        <framequat name="right_foot_site_quat" objtype="site" objname="right_foot_site"/>

        <user name="cf1" needstage="acc" datatype="real" dim="1"/>
    </sensor>

    <!-- <equality>
        <joint name="Neck_Yaw_lock" joint1="Neck_Yaw" polycoef="0 0 0 0 0"/>
        <joint name="Waist_Yaw_lock" joint1="Waist_Yaw" polycoef="0 0 0 0 0"/>

        <joint name="Left_Hip_Yaw_lock" joint1="Left_Hip_Yaw" polycoef="0 0 0 0 0"/>
        <joint name="Right_Hip_Yaw_lock" joint1="Right_Hip_Yaw" polycoef="0 0 0 0 0"/>
        
        <joint name="Left_Hip_Roll_lock" joint1="Left_Hip_Roll" polycoef="0 0 0 0 0"/>
        <joint name="Right_Hip_Roll_lock" joint1="Right_Hip_Roll" polycoef="-0.174 0 0 0 0"/>
        
        <joint name="Left_Hip_Pitch_lock" joint1="Left_Hip_Pitch" polycoef="-0.707 0 0 0 0"/>
        <joint name="Right_Hip_Pitch_lock" joint1="Right_Hip_Pitch" polycoef="0 0 0 0 0"/>

        <joint name="Left_Knee_Pitch_lock" joint1="Left_Knee_Pitch" polycoef="1.5 0 0 0 0"/>
        <joint name="Right_Knee_Pitch_lock" joint1="Right_Knee_Pitch" polycoef="0 0 0 0 0"/>

        <joint name="Left_Ankle_Pitch_lock" joint1="Left_Ankle_Pitch" polycoef="0 0 0 0 0"/>
        <joint name="Right_Ankle_Pitch_lock" joint1="Right_Ankle_Pitch" polycoef="-.057 0 0 0 0"/>

        <joint name="Left_Ankle_Roll_lock" joint1="Left_Ankle_Roll" polycoef="0 0 0 0 0"/>
        <joint name="Right_Ankle_Roll_lock" joint1="Right_Ankle_Roll" polycoef="-0.104 0 0 0 0"/>
      
        <joint name="Left_Shoulder_Pitch_lock" joint1="Left_Shoulder_Pitch" polycoef="0 0 0 0 0"/>
        <joint name="Right_Shoulder_Pitch_lock" joint1="Right_Shoulder_Pitch" polycoef="0 0 0 0 0"/>

        <joint name="Left_Shoulder_Roll_lock" joint1="Left_Shoulder_Roll" polycoef="-0.04712 0 0 0 0"/>
        <joint name="Right_Shoulder_Roll_lock" joint1="Right_Shoulder_Roll" polycoef="-0.04712 0 0 0 0"/>

        <joint name="Left_Arm_Yaw_lock" joint1="Left_Arm_Yaw" polycoef="-0.37696 0 0 0 0"/>
        <joint name="Right_Arm_Yaw_lock" joint1="Right_Arm_Yaw" polycoef="0.37696 0 0 0 0"/>

        <joint name="Left_Elbow_Pitch_lock" joint1="Left_Elbow_Pitch" polycoef="-1.67276 0 0 0 0"/>
        <joint name="Right_Elbow_Pitch_lock" joint1="Right_Elbow_Pitch" polycoef="-1.67276 0 0 0 0"/>
    </equality> -->
    
    <visual>
        <global offwidth="1280" offheight="720"/>
    </visual>
    
</mujoco>
